{
 "cells": [
  {
   "cell_type": "code",
   "execution_count": 7,
   "metadata": {},
   "outputs": [
    {
     "name": "stderr",
     "output_type": "stream",
     "text": [
      "WARNING: Retrying (Retry(total=4, connect=None, read=None, redirect=None, status=None)) after connection broken by 'ConnectTimeoutError(<pip._vendor.urllib3.connection.VerifiedHTTPSConnection object at 0x00000000045ED070>, 'Connection to pypi.org timed out. (connect timeout=15)')': /simple/opencv-python/\n",
      "WARNING: Retrying (Retry(total=3, connect=None, read=None, redirect=None, status=None)) after connection broken by 'ConnectTimeoutError(<pip._vendor.urllib3.connection.VerifiedHTTPSConnection object at 0x0000000004548250>, 'Connection to pypi.org timed out. (connect timeout=15)')': /simple/opencv-python/\n",
      "WARNING: Retrying (Retry(total=2, connect=None, read=None, redirect=None, status=None)) after connection broken by 'ConnectTimeoutError(<pip._vendor.urllib3.connection.VerifiedHTTPSConnection object at 0x00000000045489D0>, 'Connection to pypi.org timed out. (connect timeout=15)')': /simple/opencv-python/\n",
      "WARNING: Retrying (Retry(total=1, connect=None, read=None, redirect=None, status=None)) after connection broken by 'ConnectTimeoutError(<pip._vendor.urllib3.connection.VerifiedHTTPSConnection object at 0x0000000004548AC0>, 'Connection to pypi.org timed out. (connect timeout=15)')': /simple/opencv-python/\n",
      "WARNING: Retrying (Retry(total=0, connect=None, read=None, redirect=None, status=None)) after connection broken by 'ConnectTimeoutError(<pip._vendor.urllib3.connection.VerifiedHTTPSConnection object at 0x0000000004548550>, 'Connection to pypi.org timed out. (connect timeout=15)')': /simple/opencv-python/\n",
      "ERROR: Could not find a version that satisfies the requirement opencv-python (from versions: none)\n",
      "ERROR: No matching distribution found for opencv-python\n"
     ]
    }
   ],
   "source": [
    "!pip install opencv-python"
   ]
  },
  {
   "cell_type": "code",
   "execution_count": 4,
   "metadata": {},
   "outputs": [
    {
     "data": {
      "text/plain": [
       "5"
      ]
     },
     "execution_count": 4,
     "metadata": {},
     "output_type": "execute_result"
    }
   ],
   "source": [
    "3+2"
   ]
  },
  {
   "cell_type": "code",
   "execution_count": 5,
   "metadata": {},
   "outputs": [
    {
     "name": "stdout",
     "output_type": "stream",
     "text": [
      "$PATH\n"
     ]
    }
   ],
   "source": [
    "!echo $PATH"
   ]
  },
  {
   "cell_type": "code",
   "execution_count": 6,
   "metadata": {},
   "outputs": [
    {
     "name": "stdout",
     "output_type": "stream",
     "text": [
      "Collecting package metadata (current_repodata.json): ...working... failed\n"
     ]
    },
    {
     "name": "stderr",
     "output_type": "stream",
     "text": [
      "\n",
      "CondaHTTPError: HTTP 000 CONNECTION FAILED for url <https://repo.anaconda.com/pkgs/main/win-64/current_repodata.json>\n",
      "Elapsed: -\n",
      "\n",
      "An HTTP error occurred when trying to retrieve this URL.\n",
      "HTTP errors are often intermittent, and a simple retry will get you on your way.\n",
      "\n",
      "If your current network has https://www.anaconda.com blocked, please file\n",
      "a support request with your network engineering team.\n",
      "\n",
      "'https://repo.anaconda.com/pkgs/main/win-64'\n",
      "\n",
      "\n",
      "WARNING: Retrying (Retry(total=4, connect=None, read=None, redirect=None, status=None)) after connection broken by 'ConnectTimeoutError(<pip._vendor.urllib3.connection.VerifiedHTTPSConnection object at 0x00000000045DC130>, 'Connection to pypi.org timed out. (connect timeout=15)')': /simple/opencv-python/\n",
      "WARNING: Retrying (Retry(total=3, connect=None, read=None, redirect=None, status=None)) after connection broken by 'ConnectTimeoutError(<pip._vendor.urllib3.connection.VerifiedHTTPSConnection object at 0x0000000004538220>, 'Connection to pypi.org timed out. (connect timeout=15)')': /simple/opencv-python/\n",
      "WARNING: Retrying (Retry(total=2, connect=None, read=None, redirect=None, status=None)) after connection broken by 'ConnectTimeoutError(<pip._vendor.urllib3.connection.VerifiedHTTPSConnection object at 0x0000000004538580>, 'Connection to pypi.org timed out. (connect timeout=15)')': /simple/opencv-python/\n",
      "WARNING: Retrying (Retry(total=1, connect=None, read=None, redirect=None, status=None)) after connection broken by 'ConnectTimeoutError(<pip._vendor.urllib3.connection.VerifiedHTTPSConnection object at 0x0000000004538A90>, 'Connection to pypi.org timed out. (connect timeout=15)')': /simple/opencv-python/\n",
      "WARNING: Retrying (Retry(total=0, connect=None, read=None, redirect=None, status=None)) after connection broken by 'ConnectTimeoutError(<pip._vendor.urllib3.connection.VerifiedHTTPSConnection object at 0x0000000004538880>, 'Connection to pypi.org timed out. (connect timeout=15)')': /simple/opencv-python/\n",
      "ERROR: Could not find a version that satisfies the requirement opencv-python (from versions: none)\n",
      "ERROR: No matching distribution found for opencv-python\n"
     ]
    }
   ],
   "source": [
    "import sys\n",
    "!conda install --yes --prefix {sys.prefix} numpy"
   ]
  },
  {
   "cell_type": "code",
   "execution_count": null,
   "metadata": {},
   "outputs": [],
   "source": []
  }
 ],
 "metadata": {
  "kernelspec": {
   "display_name": "Python 3",
   "language": "python",
   "name": "python3"
  },
  "language_info": {
   "codemirror_mode": {
    "name": "ipython",
    "version": 3
   },
   "file_extension": ".py",
   "mimetype": "text/x-python",
   "name": "python",
   "nbconvert_exporter": "python",
   "pygments_lexer": "ipython3",
   "version": "3.8.3"
  }
 },
 "nbformat": 4,
 "nbformat_minor": 4
}
